2022-10-03 16:37:05,626 ERROR: Exception on /follow/susan [POST] [in D:\microblog\venv\lib\site-packages\flask\app.py:1741]
Traceback (most recent call last):
  File "D:\microblog\venv\lib\site-packages\flask\app.py", line 2525, in wsgi_app
    response = self.full_dispatch_request()
  File "D:\microblog\venv\lib\site-packages\flask\app.py", line 1822, in full_dispatch_request
    rv = self.handle_user_exception(e)
  File "D:\microblog\venv\lib\site-packages\flask\app.py", line 1820, in full_dispatch_request
    rv = self.dispatch_request()
  File "D:\microblog\venv\lib\site-packages\flask\app.py", line 1796, in dispatch_request
    return self.ensure_sync(self.view_functions[rule.endpoint])(**view_args)
  File "D:\microblog\venv\lib\site-packages\flask_login\utils.py", line 290, in decorated_view
    return current_app.ensure_sync(func)(*args, **kwargs)
  File "D:\microblog\app\routes.py", line 108, in follow
    current_user.follow(username)
  File "D:\microblog\app\models.py", line 48, in follow
    if not self.is_following(user):
  File "D:\microblog\app\models.py", line 56, in is_following
    return self.followed.filter(followers.c.followed_id == user.id).count() > 0
AttributeError: 'str' object has no attribute 'id'
2022-10-03 16:52:26,446 INFO: Microblog startup [in D:\microblog\app\__init__.py:52]
2022-10-03 16:55:19,874 ERROR: Exception on /follow/susan [POST] [in D:\microblog\venv\lib\site-packages\flask\app.py:1741]
Traceback (most recent call last):
  File "D:\microblog\venv\lib\site-packages\flask\app.py", line 2525, in wsgi_app
    response = self.full_dispatch_request()
  File "D:\microblog\venv\lib\site-packages\flask\app.py", line 1822, in full_dispatch_request
    rv = self.handle_user_exception(e)
  File "D:\microblog\venv\lib\site-packages\flask\app.py", line 1820, in full_dispatch_request
    rv = self.dispatch_request()
  File "D:\microblog\venv\lib\site-packages\flask\app.py", line 1796, in dispatch_request
    return self.ensure_sync(self.view_functions[rule.endpoint])(**view_args)
  File "D:\microblog\venv\lib\site-packages\flask_login\utils.py", line 290, in decorated_view
    return current_app.ensure_sync(func)(*args, **kwargs)
  File "D:\microblog\app\routes.py", line 108, in follow
    current_user.follow(username)
  File "D:\microblog\app\models.py", line 48, in follow
    if not self.is_following(user):
  File "D:\microblog\app\models.py", line 57, in is_following
    return self.followed.filter(followers.c.followed_id == user.id).count() > 0
AttributeError: 'str' object has no attribute 'id'
2022-10-03 17:04:52,907 INFO: Microblog startup [in D:\microblog\app\__init__.py:52]
2022-10-03 17:05:01,260 ERROR: Exception on /follow/susan [POST] [in D:\microblog\venv\lib\site-packages\flask\app.py:1741]
Traceback (most recent call last):
  File "D:\microblog\venv\lib\site-packages\flask\app.py", line 2525, in wsgi_app
    response = self.full_dispatch_request()
  File "D:\microblog\venv\lib\site-packages\flask\app.py", line 1822, in full_dispatch_request
    rv = self.handle_user_exception(e)
  File "D:\microblog\venv\lib\site-packages\flask\app.py", line 1820, in full_dispatch_request
    rv = self.dispatch_request()
  File "D:\microblog\venv\lib\site-packages\flask\app.py", line 1796, in dispatch_request
    return self.ensure_sync(self.view_functions[rule.endpoint])(**view_args)
  File "D:\microblog\venv\lib\site-packages\flask_login\utils.py", line 290, in decorated_view
    return current_app.ensure_sync(func)(*args, **kwargs)
  File "D:\microblog\app\routes.py", line 111, in follow
    return redirect(url_for("user"), username=username)
  File "D:\microblog\venv\lib\site-packages\flask\helpers.py", line 256, in url_for
    return current_app.url_for(
  File "D:\microblog\venv\lib\site-packages\flask\app.py", line 2031, in url_for
    return self.handle_url_build_error(error, endpoint, values)
  File "D:\microblog\venv\lib\site-packages\flask\app.py", line 2020, in url_for
    rv = url_adapter.build(  # type: ignore[union-attr]
  File "D:\microblog\venv\lib\site-packages\werkzeug\routing\map.py", line 917, in build
    raise BuildError(endpoint, values, method, self)
werkzeug.routing.exceptions.BuildError: Could not build url for endpoint 'user'. Did you forget to specify values ['username']?
2022-10-03 17:10:00,551 INFO: Microblog startup [in D:\microblog\app\__init__.py:52]
